Workbook

Sheet README
B2: BCEA-COMPLIANT WORKFORCE MANAGEMENT SYSTEM Employee List & Payroll Rate Engine | Wholesale & Retail Sector
B4: Built by Keith Coetzee | linkedin.com/in/keithcoetzeeza | github.com/KeithCoetzee-ZA
B6: WHAT THIS SYSTEM DOES
B8: This is not a list of employees. It is a BCEA-compliant workforce management engine built around the Wholesale and Retail Sector Determination, governing minimum wages, contract classification, overtime eligibility, and payroll rate derivation for up to 195 employees across multiple departments and roles. The system is designed so that compliance is structural, not procedural. The correct rate for any employee, under any contract type, in any gazette-defined role, is derived automatically from the legislation - not entered manually, not looked up, not trusted to memory. The law is built into the architecture.
B10: SHEET ARCHITECTURE
B12: Emp_List (Master Register) | C12: The operational spine of the system. Employee numbers auto-increment from a defined start point. Designations are controlled via dropdown - only gazette-recognised role names are selectable, eliminating free-text entry errors that would break downstream rate lookups. Contract type is classified as P (Permanent), M (Manager/Owner - excluded from planning rosters), C (above 27 hours), or D (below 27 hours) - the 27-hour threshold being the legislative boundary under the Sectoral Determination that triggers different minimum wage obligations. Role codes are derived via XLOOKUP from the Role_codes sheet the moment a designation is selected. Active/Inactive flagging controls which employees pull through to HR_Private. Conditional formatting fires on data presence - borders appear only on populated rows, keeping the register clean at scale.
B13: Gazetted_Rates (Compliance Foundation) | C13: The legislative layer. Wholesale and Retail Sectoral Determination minimum wage rates are captured here by role, split across the two rate columns that correspond to the sub-27-hour and above-27-hour thresholds (CI 2(3)(b) and CI 2(3)(a) respectively). This sheet is the single update point for each new financial year - change the gazette rates here, and the correction propagates automatically through every downstream calculation in the system. No employee record needs to be touched. No formula needs to be rewritten. Compliance updates in one place.
B14: Role_codes (Translation Layer) | C14: The bridge between human-readable designations and payroll-executable data. Every gazette-recognised role maps to a role code, a full extended description, and both gazette rate columns. When HR_Private needs to derive a rate for a specific employee, it uses this sheet via XLOOKUP with CHOOSECOLS - selecting the correct rate column (sub-27hr or above-27hr) based on the employee's contract type classification. The system never applies the wrong rate to the wrong contract type because the selection logic is encoded in the formula, not left to the person running payroll.
B15: HR_Private (Protected Payroll Layer) | C15: The payroll execution sheet - access-controlled, selectively unlocked, and structurally separated from the operational register. Active employees are pulled from Emp_List using a FILTER function with SORTBY, sorted by Surname then Name, updating automatically as the master register changes. Hourly rates for gazette employees are derived from Role_codes based on contract type. Monthly salaries for permanent and management employees are captured in the unlocked salary column. The overtime conversion formula (monthly salary ÷ 180) produces the hourly equivalent required for overtime calculations under the BCEA - automatically, for every salaried employee, without manual intervention. The Roster Cost Rate column distinguishes between the gazette rate (for planning) and the actual rate (for payroll), ensuring that workforce planning and cost modelling draw from the correct figure for their respective purposes.
B16: DocInfo & Library (Build Documentation) | C16: The system's own technical manual. Formula construction notes, conditional formatting rules, cell protection specifications, unlocked range definitions, and dropdown list source data are all documented here in structured format with colour-coded instruction categories. Any competent Excel user can reconstruct, extend, or maintain this system from this sheet alone. It is the difference between a tool that works and a tool that lasts.
B18: COMPLIANCE BY DESIGN - NOT BY PROCEDURE
B20: 27-Hour Threshold | C20: The BCEA and Wholesale & Retail Sectoral Determination create two distinct minimum wage obligations based on contracted hours. This system encodes that boundary as a contract type classifier (C/>27hrs, D/<27hrs) and uses it to drive rate selection automatically. The person capturing employees does not need to know the gazette. They select the contract type. The system applies the law.
B21: Gazette Rate Propagation | C21: When the Department of Labour publishes revised sectoral minimum wages each financial year, one update to the Gazetted_Rates sheet cascades through Role_codes and HR_Private simultaneously. Every employee's derived rate updates without any further intervention. Compliance is maintained at system level.
B22: Overtime Rate Derivation | C22: The BCEA requires overtime to be calculated at 1.5x the employee's ordinary hourly rate. For monthly-salaried employees, that hourly rate is not stated - it must be derived. This system applies the standard 180-hour conversion (monthly salary ÷ 180) automatically for every permanent and management employee, producing the base hourly rate from which overtime can be correctly calculated downstream in the planning rosters.
B23: Roster Exclusion Logic | C23: Management and owner-level employees (Contract Type M) are flagged to exclude from planning rosters - they appear in HR_Private for payroll purposes but do not pull through to shift planning tools. This prevents their cost rates from distorting hourly workforce planning calculations that are built around gazette-rate employees.
B24: Access Control Architecture | C24: Sheet protection with selective unlocking ensures data integrity at scale. In Emp_List, only the employee data input range is unlocked - structural columns are protected. In HR_Private, only the salary capture column is unlocked - all derived fields are formula-protected. In Gazetted_Rates, only the annual rate update cell is unlocked. Role_codes is fully locked. The system is designed to be used correctly by default.
B26: LEGISLATIVE CONTEXT
B28: This system is built on the Basic Conditions of Employment Act (BCEA) and the Wholesale and Retail Sector Sectoral Determination issued under it. The Sectoral Determination sets minimum wages by role and contracted hours for the sector, updated annually by the Department of Labour. The 27-hour weekly threshold, the role classifications, the rate differentials, and the overtime calculation methodology are all statutory obligations - not operational preferences. Building compliance into system architecture rather than relying on procedural adherence is the difference between a workforce management tool and a liability. This system is the former.
B30: github.com/KeithCoetzee-ZA | linkedin.com/in/keithcoetzeeza | Available immediately | Remote-ready

Sheet DocInfo & Library
A1: --W/S Emp_List--
A2: --=Copy Formatting in from the Master Template, for first 5 rows from A1--
A3: $A6=First Employee number
A4: SA7=A6+1
A6: --Drop down list for Designations--
A7: --Gen. Asst., Sec.Guard, Forklift Op., Driver, Merchandiser, Cashier, Clerk, Sales Asst., BlockMan, Baker, Deli Asst., Supervisor, Trainee Man., Asst. Manager, Manager--
A8: --Drop Down List for Contract Type--
A9: --P, M, C, D (P=Permanent, pulls into planning rosters. M=Store Manager/Owner, does not pull into planning rosters. C=>27 Hours, for hourly rates as per Gazette. D=<27 Hours, for hourly rates as per Gazette)--
A10: --Role Codes - to pull the role code in for the Designation selected from the previous drop down menu, in $F6--
A11: =XLOOKUP($D7, Role_codes!$B$2:$B$16, Role_codes!$A$2:$A$16, "") --Copy, and paste the formula down to row 200--
A13: --Conditional Formatting
A14: =$A6>0
... A68: =$A$1:$A$77

Sheet Emp_List
A1: COMPANY LOGO/BRANDING
A4: SHEET NAME
A5: Emp_Num | B5: Name | C5: Surname | D5: Designation | E5: Department | F5: Contract Type | G5: Role Codes | H5: Active Yes/No
A6: 1001 | G6: =_xlfn.XLOOKUP($D6, Role_codes!$B$2:$B$16, Role_codes!$A$2:$A$16, "")
A7: =A6+1 -> 1002 | G7: =_xlfn.XLOOKUP($D7, Role_codes!$B$2:$B$16, Role_codes!$A$2:$A$16, "")
A8: =A7+1 -> 1003 | G8: =_xlfn.XLOOKUP($D8, Role_codes!$B$2:$B$16, Role_codes!$A$2:$A$16, "")
A9: =A8+1 -> 1004 | G9: =_xlfn.XLOOKUP($D9, Role_codes!$B$2:$B$16, Role_codes!$A$2:$A$16, "")
A10: =A9+1 -> 1005 | G10: =_xlfn.XLOOKUP($D10, Role_codes!$B$2:$B$16, Role_codes!$A$2:$A$16, "")
A11: =A10+1 -> 1006 | G11: =_xlfn.XLOOKUP($D11, Role_codes!$B$2:$B$16, Role_codes!$A$2:$A$16, "")
A12: =A11+1 -> 1007 | G12: =_xlfn.XLOOKUP($D12, Role_codes!$B$2:$B$16, Role_codes!$A$2:$A$16, "")
A13: =A12+1 -> 1008 | G13: =_xlfn.XLOOKUP($D13, Role_codes!$B$2:$B$16, Role_codes!$A$2:$A$16, "")
A14: =A13+1 -> 1009 | G14: =_xlfn.XLOOKUP($D14, Role_codes!$B$2:$B$16, Role_codes!$A$2:$A$16, "")
A15: =A14+1 -> 1010 | G15: =_xlfn.XLOOKUP($D15, Role_codes!$B$2:$B$16, Role_codes!$A$2:$A$16, "")
A16: =A15+1 -> 1011 | G16: =_xlfn.XLOOKUP($D16, Role_codes!$B$2:$B$16, Role_codes!$A$2:$A$16, "")
A17: =A16+1 -> 1012 | G17: =_xlfn.XLOOKUP($D17, Role_codes!$B$2:$B$16, Role_codes!$A$2:$A$16, "")
A18: =A17+1 -> 1013 | G18: =_xlfn.XLOOKUP($D18, Role_codes!$B$2:$B$16, Role_codes!$A$2:$A$16, "")
... A44: =A43+1 -> 1039 | G44: =_xlfn.XLOOKUP($D44, Role_codes!$B$2:$B$16, Role_codes!$A$2:$A$16, "")
A45: =A44+1 -> 1040 | B45: Juan | C45: Carlos | D45: Sales Asst. | E45: Bakery | F45: D | G45: =_xlfn.XLOOKUP($D45, Role_codes!$B$2:$B$16, Role_codes!$A$2:$A$16, "") -> SAL01 | H45: YES
A46: =A45+1 -> 1041 | G46: =_xlfn.XLOOKUP($D46, Role_codes!$B$2:$B$16, Role_codes!$A$2:$A$16, "")
A47: =A46+1 -> 1042 | G47: =_xlfn.XLOOKUP($D47, Role_codes!$B$2:$B$16, Role_codes!$A$2:$A$16, "")
A48: =A47+1 -> 1043 | G48: =_xlfn.XLOOKUP($D48, Role_codes!$B$2:$B$16, Role_codes!$A$2:$A$16, "")
A49: =A48+1 -> 1044 | G49: =_xlfn.XLOOKUP($D49, Role_codes!$B$2:$B$16, Role_codes!$A$2:$A$16, "")
A50: =A49+1 -> 1045 | B50: Ian | C50: Mac Greggor | D50: Asst. Manager | E50: Floor | F50: M | G50: =_xlfn.XLOOKUP($D50, Role_codes!$B$2:$B$16, Role_codes!$A$2:$A$16, "") -> ASM01 | H50: YES
A51: =A50+1 -> 1046 | G51: =_xlfn.XLOOKUP($D51, Role_codes!$B$2:$B$16, Role_codes!$A$2:$A$16, "")
A52: =A51+1 -> 1047 | G52: =_xlfn.XLOOKUP($D52, Role_codes!$B$2:$B$16, Role_codes!$A$2:$A$16, "")
A53: =A52+1 -> 1048 | G53: =_xlfn.XLOOKUP($D53, Role_codes!$B$2:$B$16, Role_codes!$A$2:$A$16, "")
A54: =A53+1 -> 1049 | G54: =_xlfn.XLOOKUP($D54, Role_codes!$B$2:$B$16, Role_codes!$A$2:$A$16, "")
A55: =A54+1 -> 1050 | G55: =_xlfn.XLOOKUP($D55, Role_codes!$B$2:$B$16, Role_codes!$A$2:$A$16, "")
A56: =A55+1 -> 1051 | G56: =_xlfn.XLOOKUP($D56, Role_codes!$B$2:$B$16, Role_codes!$A$2:$A$16, "")
A57: =A56+1 -> 1052 | G57: =_xlfn.XLOOKUP($D57, Role_codes!$B$2:$B$16, Role_codes!$A$2:$A$16, "")
A58: =A57+1 -> 1053 | B58: Ann | C58: Juco | D58: Sales Asst. | E58: Floor | F58: C | G58: =_xlfn.XLOOKUP($D58, Role_codes!$B$2:$B$16, Role_codes!$A$2:$A$16, "") -> SAL01 | H58: YES
A59: =A58+1 -> 1054 | G59: =_xlfn.XLOOKUP($D59, Role_codes!$B$2:$B$16, Role_codes!$A$2:$A$16, "")
A60: =A59+1 -> 1055 | G60: =_xlfn.XLOOKUP($D60, Role_codes!$B$2:$B$16, Role_codes!$A$2:$A$16, "")
A61: =A60+1 -> 1056 | G61: =_xlfn.XLOOKUP($D61, Role_codes!$B$2:$B$16, Role_codes!$A$2:$A$16, "")
A62: =A61+1 -> 1057 | G62: =_xlfn.XLOOKUP($D62, Role_codes!$B$2:$B$16, Role_codes!$A$2:$A$16, "")
A63: =A62+1 -> 1058 | G63: =_xlfn.XLOOKUP($D63, Role_codes!$B$2:$B$16, Role_codes!$A$2:$A$16, "")
A64: =A63+1 -> 1059 | G64: =_xlfn.XLOOKUP($D64, Role_codes!$B$2:$B$16, Role_codes!$A$2:$A$16, "")
A65: =A64+1 -> 1060 | G65: =_xlfn.XLOOKUP($D65, Role_codes!$B$2:$B$16, Role_codes!$A$2:$A$16, "")
A66: =A65+1 -> 1061 | G66: =_xlfn.XLOOKUP($D66, Role_codes!$B$2:$B$16, Role_codes!$A$2:$A$16, "")
A67: =A66+1 -> 1062 | G67: =_xlfn.XLOOKUP($D67, Role_codes!$B$2:$B$16, Role_codes!$A$2:$A$16, "")
...

Sheet Gazetted_Rates
A1: WHOLESALE & RETAIL MINIMUM WAGE TABLE (Area B)
A2: Minimum wages for the period
A3: 1/02/2017 to 31/01/2018
A4: Job Category | B4: 27Hrs or Less
B5: CI 2(3)(b) | C5: CI 2(3)(a)
B6: R.p.h
A7: General Assistant/Trolley Controller | B7: 15.76 | C7: 19.7
A8: Security Guard | B8: 17.39 | C8: 21.74
A9: Forklift Operator | B9: 15.87 | C9: 19.84
A10: Driver <3500kg | B10: 16.28 | C10: 20.35
A11: Merchandiser/ Shop Assistant/ Checker | B11: 17.13 | C11: 21.42
A12: Cashier | B12: 18.16 | C12: 22.71
A13: Driver 3501 <9000kg | B13: 19.47 | C13: 24.33
A14: Clerk/Sales Assistant/ Sales Person/ Block Man/ Baker/ Deli Assistant | B14: 21.5 | C14: 26.88
A15: Driver 9001<16000kg | B15: 23.29 | C15: 29.11
A16: Displayer | B16: 20.73 | C16: 25.92
A17: 09Driver 16001kg> | B17: 25.6 | C17: 31.99
A18: Supervisor | B18: 26.03 | C18: 32.54
... A21: Manager | B21: 33.3 | C21: 41.62

Sheet HR_Private
A1: COMPANY LOGO/BRANDING
L2: Salary
L3: Convert
A4: EMPLOYEE PAYROLL | K4: Roster | L4: Hourly
A5: Emp_Num | B5: Name | C5: Surname | D5: Designation | E5: Department | F5: Contract Type | G5: Role Codes | H5: Active Yes/No | I5: Rate | J5: Salary Monthly | K5: Cost Rate | L5: Base Rate
A6: {=IFERROR(_xlfn.SORTBY(_xlfn._xlws.FILTER(Emp_List!$A$6:$H$200, Emp_List!$H$6:$H$200="YES"), _xlfn._xlws.FILTER(Emp_List!$C$6:$C$200, Emp_List!$H$6:$H$200="YES"), 1, _xlfn._xlws.FILTER(Emp_List!$B$6:$B$200, Emp_List!$H$6:$H$200="YES"), 1),"")} -> 1083 | B6: Marty | C6: Blythe | D6: Manager | E6: Management | F6: M | G6: MAN01 | H6: YES | I6: {=IF(OR($F6="P",$F6="M"),"", _xlfn.XLOOKUP($G6, Role_codes!$A$2:$A$16, _xlfn.CHOOSECOLS(Role_codes!$D$2:$E$16, IF($F6="C",1,2)),""))} | J6: 8000 | K6: =IF(OR($F6="P",$F6="M"), J6, I6) -> 8000 | L6: =IF($A7="","", IF(OR($F6="P",$F6="M"), $J6/180, $J6)) -> 44.444444
A7: 1040 | B7: Juan | C7: Carlos | D7: Sales Asst. | E7: Bakery | F7: D | G7: SAL01 | H7: YES | I7: {=IF(OR($F7="P",$F7="M"),"", _xlfn.XLOOKUP($G7, Role_codes!$A$2:$A$16, _xlfn.CHOOSECOLS(Role_codes!$D$2:$E$16, IF($F7="C",1,2)),""))} -> 26.88 | K7: =IF(OR($F7="P",$F7="M"), J7, I7) -> 26.88 | L7: =IF($A8="","", IF(OR($F7="P",$F7="M"), $J7/180, $J7)) -> 0
A8: 1065 | B8: Carlo | C8: Juan | D8: Baker | E8: Bakery | F8: P | G8: BAK01 | H8: YES | I8: {=IF(OR($F8="P",$F8="M"),"", _xlfn.XLOOKUP($G8, Role_codes!$A$2:$A$16, _xlfn.CHOOSECOLS(Role_codes!$D$2:$E$16, IF($F8="C",1,2)),""))} | J8: 5000 | K8: =IF(OR($F8="P",$F8="M"), J8, I8) -> 5000 | L8: =IF($A9="","", IF(OR($F8="P",$F8="M"), $J8/180, $J8)) -> 27.777778
A9: 1053 | B9: Ann | C9: Juco | D9: Sales Asst. | E9: Floor | F9: C | G9: SAL01 | H9: YES | I9: {=IF(OR($F9="P",$F9="M"),"", _xlfn.XLOOKUP($G9, Role_codes!$A$2:$A$16, _xlfn.CHOOSECOLS(Role_codes!$D$2:$E$16, IF($F9="C",1,2)),""))} -> 21.5 | K9: =IF(OR($F9="P",$F9="M"), J9, I9) -> 21.5 | L9: =IF($A10="","", IF(OR($F9="P",$F9="M"), $J9/180, $J9)) -> 0
A10: 1045 | B10: Ian | C10: Mac Greggor | D10: Asst. Manager | E10: Floor | F10: M | G10: ASM01 | H10: YES | I10: {=IF(OR($F10="P",$F10="M"),"", _xlfn.XLOOKUP($G10, Role_codes!$A$2:$A$16, _xlfn.CHOOSECOLS(Role_codes!$D$2:$E$16, IF($F10="C",1,2)),""))} | K10: =IF(OR($F10="P",$F10="M"), J10, I10) -> 0 | L10: =IF($A11="","", IF(OR($F10="P",$F10="M"), $J10/180, $J10))
I11: {=IF(OR($F11="P",$F11="M"),"", _xlfn.XLOOKUP($G11, Role_codes!$A$2:$A$16, _xlfn.CHOOSECOLS(Role_codes!$D$2:$E$16, IF($F11="C",1,2)),""))} | K11: =IF(OR($F11="P",$F11="M"), J11, I11) | L11: =IF($A12="","", IF(OR($F11="P",$F11="M"), $J11/180, $J11))
I12: {=IF(OR($F12="P",$F12="M"),"", _xlfn.XLOOKUP($G12, Role_codes!$A$2:$A$16, _xlfn.CHOOSECOLS(Role_codes!$D$2:$E$16, IF($F12="C",1,2)),""))} | K12: =IF(OR($F12="P",$F12="M"), J12, I12) | L12: =IF($A13="","", IF(OR($F12="P",$F12="M"), $J12/180, $J12))
I13: {=IF(OR($F13="P",$F13="M"),"", _xlfn.XLOOKUP($G13, Role_codes!$A$2:$A$16, _xlfn.CHOOSECOLS(Role_codes!$D$2:$E$16, IF($F13="C",1,2)),""))} | K13: =IF(OR($F13="P",$F13="M"), J13, I13) | L13: =IF($A14="","", IF(OR($F13="P",$F13="M"), $J13/180, $J13))
I14: {=IF(OR($F14="P",$F14="M"),"", _xlfn.XLOOKUP($G14, Role_codes!$A$2:$A$16, _xlfn.CHOOSECOLS(Role_codes!$D$2:$E$16, IF($F14="C",1,2)),""))} | K14: =IF(OR($F14="P",$F14="M"), J14, I14) | L14: =IF($A15="","", IF(OR($F14="P",$F14="M"), $J14/180, $J14))
I15: {=IF(OR($F15="P",$F15="M"),"", _xlfn.XLOOKUP($G15, Role_codes!$A$2:$A$16, _xlfn.CHOOSECOLS(Role_codes!$D$2:$E$16, IF($F15="C",1,2)),""))} | K15: =IF(OR($F15="P",$F15="M"), J15, I15) | L15: =IF($A16="","", IF(OR($F15="P",$F15="M"), $J15/180, $J15))
I16: {=IF(OR($F16="P",$F16="M"),"", _xlfn.XLOOKUP($G16, Role_codes!$A$2:$A$16, _xlfn.CHOOSECOLS(Role_codes!$D$2:$E$16, IF($F16="C",1,2)),""))} | K16: =IF(OR($F16="P",$F16="M"), J16, I16) | L16: =IF($A17="","", IF(OR($F16="P",$F16="M"), $J16/180, $J16))
I17: {=IF(OR($F17="P",$F17="M"),"", _xlfn.XLOOKUP($G17, Role_codes!$A$2:$A$16, _xlfn.CHOOSECOLS(Role_codes!$D$2:$E$16, IF($F17="C",1,2)),""))} | K17: =IF(OR($F17="P",$F17="M"), J17, I17) | L17: =IF($A18="","", IF(OR($F17="P",$F17="M"), $J17/180, $J17))
I18: {=IF(OR($F18="P",$F18="M"),"", _xlfn.XLOOKUP($G18, Role_codes!$A$2:$A$16, _xlfn.CHOOSECOLS(Role_codes!$D$2:$E$16, IF($F18="C",1,2)),""))} | K18: =IF(OR($F18="P",$F18="M"), J18, I18) | L18: =IF($A19="","", IF(OR($F18="P",$F18="M"), $J18/180, $J18))
I19: {=IF(OR($F19="P",$F19="M"),"", _xlfn.XLOOKUP($G19, Role_codes!$A$2:$A$16, _xlfn.CHOOSECOLS(Role_codes!$D$2:$E$16, IF($F19="C",1,2)),""))} | K19: =IF(OR($F19="P",$F19="M"), J19, I19) | L19: =IF($A20="","", IF(OR($F19="P",$F19="M"), $J19/180, $J19))
I20: {=IF(OR($F20="P",$F20="M"),"", _xlfn.XLOOKUP($G20, Role_codes!$A$2:$A$16, _xlfn.CHOOSECOLS(Role_codes!$D$2:$E$16, IF($F20="C",1,2)),""))} | K20: =IF(OR($F20="P",$F20="M"), J20, I20) | L20: =IF($A21="","", IF(OR($F20="P",$F20="M"), $J20/180, $J20))
I21: {=IF(OR($F21="P",$F21="M"),"", _xlfn.XLOOKUP($G21, Role_codes!$A$2:$A$16, _xlfn.CHOOSECOLS(Role_codes!$D$2:$E$16, IF($F21="C",1,2)),""))} | K21: =IF(OR($F21="P",$F21="M"), J21, I21) | L21: =IF($A22="","", IF(OR($F21="P",$F21="M"), $J21/180, $J21))
I22: {=IF(OR($F22="P",$F22="M"),"", _xlfn.XLOOKUP($G22, Role_codes!$A$2:$A$16, _xlfn.CHOOSECOLS(Role_codes!$D$2:$E$16, IF($F22="C",1,2)),""))} | K22: =IF(OR($F22="P",$F22="M"), J22, I22) | L22: =IF($A23="","", IF(OR($F22="P",$F22="M"), $J22/180, $J22))
... I200: {=IF(OR($F200="P",$F200="M"),"", _xlfn.XLOOKUP($G200, Role_codes!$A$2:$A$16, _xlfn.CHOOSECOLS(Role_codes!$D$2:$E$16, IF($F200="C",1,2)),""))} | K200: =IF(OR($F200="P",$F200="M"), J200, I200) | L200: =IF($A201="","", IF(OR($F200="P",$F200="M"), $J200/180, $J200))

Sheet Role_codes
A1: Role Code | B1: Role Name | C1: Role Name - Extended | D1: Rate <27Hr | E1: Rate >27Hr
A2: GEN01 | B2: Gen. Asst. | C2: General Assistant/Trolley Controller | D2: =Gazetted_Rates!B7 -> 15.76 | E2: =Gazetted_Rates!C7 -> 19.7
A3: SEC01 | B3: Sec.Guard | C3: Security Guard | D3: =Gazetted_Rates!B8 -> 17.39 | E3: =Gazetted_Rates!C8 -> 21.74
A4: FLO01 | B4: Forklift Op | C4: Forklift Operator | D4: =Gazetted_Rates!B9 -> 15.87 | E4: =Gazetted_Rates!C9 -> 19.84
A5: DRV01 | B5: Driver | C5: Driver <3500kg | D5: =Gazetted_Rates!B10 -> 16.28 | E5: =Gazetted_Rates!C10 -> 20.35
A6: MER01 | B6: Merchandiser | C6: Merchandiser | D6: =Gazetted_Rates!B11 -> 17.13 | E6: =Gazetted_Rates!C11 -> 21.42
A7: CAS01 | B7: Cashier | C7: Cashier | D7: =Gazetted_Rates!B12 -> 18.16 | E7: =Gazetted_Rates!C12 -> 22.71
A8: CLK01 | B8: Clerk | C8: Clerk | D8: =Gazetted_Rates!B14 -> 21.5 | E8: =Gazetted_Rates!C14 -> 26.88
A9: SAL01 | B9: Sales Asst. | C9: Sales AssistantSales Person | D9: =Gazetted_Rates!B14 -> 21.5 | E9: =Gazetted_Rates!C14 -> 26.88
A10: BLO01 | B10: BlockMan | C10: Block Man | D10: =Gazetted_Rates!B14 -> 21.5 | E10: =Gazetted_Rates!C14 -> 26.88
A11: BAK01 | B11: Baker | C11: Baker | D11: =Gazetted_Rates!B14 -> 21.5 | E11: =Gazetted_Rates!C14 -> 26.88
A12: DEL01 | B12: Deli Asst. | C12: Deli Assistant | D12: =Gazetted_Rates!B14 -> 21.5 | E12: =Gazetted_Rates!C14 -> 26.88
A13: SUP01 | B13: Supervisor | C13: Supervisor | D13: =Gazetted_Rates!B18 -> 26.03 | E13: =Gazetted_Rates!C18 -> 32.54
A14: TRM01 | B14: Trainee Man. | C14: Trainee Manager | D14: =Gazetted_Rates!B19 -> 27.86 | E14: =Gazetted_Rates!C19 -> 34.82
A15: ASM01 | B15: Asst. Manager | C15: Assistant Manager | D15: =Gazetted_Rates!B20 -> 30.7 | E15: =Gazetted_Rates!C20 -> 38.38
A16: MAN01 | B16: Manager | C16: Manager | D16: =Gazetted_Rates!B21 -> 33.3 | E16: =Gazetted_Rates!C21 -> 41.62
